[2024-02-28T18:57:11.774+0000] {taskinstance.py:1956} INFO - Dependencies all met for dep_context=non-requeueable deps ti=<TaskInstance: first_dag.Test_conexion manual__2024-02-28T18:57:10.462031+00:00 [queued]>
[2024-02-28T18:57:11.778+0000] {taskinstance.py:1956} INFO - Dependencies all met for dep_context=requeueable deps ti=<TaskInstance: first_dag.Test_conexion manual__2024-02-28T18:57:10.462031+00:00 [queued]>
[2024-02-28T18:57:11.779+0000] {taskinstance.py:2170} INFO - Starting attempt 1 of 1
[2024-02-28T18:57:11.785+0000] {taskinstance.py:2191} INFO - Executing <Task(PostgresOperator): Test_conexion> on 2024-02-28 18:57:10.462031+00:00
[2024-02-28T18:57:11.789+0000] {standard_task_runner.py:60} INFO - Started process 660 to run task
[2024-02-28T18:57:11.792+0000] {standard_task_runner.py:87} INFO - Running: ['***', 'tasks', 'run', 'first_dag', 'Test_conexion', 'manual__2024-02-28T18:57:10.462031+00:00', '--job-id', '463', '--raw', '--subdir', 'DAGS_FOLDER/first_dag.py', '--cfg-path', '/tmp/tmpkibvhln3']
[2024-02-28T18:57:11.794+0000] {standard_task_runner.py:88} INFO - Job 463: Subtask Test_conexion
[2024-02-28T18:57:11.819+0000] {task_command.py:423} INFO - Running <TaskInstance: first_dag.Test_conexion manual__2024-02-28T18:57:10.462031+00:00 [running]> on host 3d1772f4008a
[2024-02-28T18:57:11.864+0000] {taskinstance.py:2480} INFO - Exporting env vars: AIRFLOW_CTX_DAG_OWNER='***' AIRFLOW_CTX_DAG_ID='first_dag' AIRFLOW_CTX_TASK_ID='Test_conexion' AIRFLOW_CTX_EXECUTION_DATE='2024-02-28T18:57:10.462031+00:00' AIRFLOW_CTX_TRY_NUMBER='1' AIRFLOW_CTX_DAG_RUN_ID='manual__2024-02-28T18:57:10.462031+00:00'
[2024-02-28T18:57:11.866+0000] {sql.py:276} INFO - Executing: SELECT 1
[2024-02-28T18:57:11.870+0000] {base.py:83} INFO - Using connection ID 'postgres1' for task execution.
[2024-02-28T18:57:11.876+0000] {base.py:83} INFO - Using connection ID 'postgres1' for task execution.
[2024-02-28T18:57:11.885+0000] {taskinstance.py:2698} ERROR - Task failed with exception
Traceback (most recent call last):
  File "/home/airflow/.local/lib/python3.8/site-packages/airflow/models/taskinstance.py", line 433, in _execute_task
    result = execute_callable(context=context, **execute_callable_kwargs)
  File "/home/airflow/.local/lib/python3.8/site-packages/airflow/providers/common/sql/operators/sql.py", line 282, in execute
    output = hook.run(
  File "/home/airflow/.local/lib/python3.8/site-packages/airflow/providers/common/sql/hooks/sql.py", line 391, in run
    with closing(self.get_conn()) as conn:
  File "/home/airflow/.local/lib/python3.8/site-packages/airflow/providers/postgres/hooks/postgres.py", line 158, in get_conn
    self.conn = psycopg2.connect(**conn_args)
  File "/home/airflow/.local/lib/python3.8/site-packages/psycopg2/__init__.py", line 122, in connect
    conn = _connect(dsn, connection_factory=connection_factory, **kwasync)
psycopg2.OperationalError: connection to server at "host.docker.internal" (192.168.65.254), port 5432 failed: FATAL:  password authentication failed for user "postgres"

[2024-02-28T18:57:11.892+0000] {taskinstance.py:1138} INFO - Marking task as FAILED. dag_id=first_dag, task_id=Test_conexion, execution_date=20240228T185710, start_date=20240228T185711, end_date=20240228T185711
[2024-02-28T18:57:11.898+0000] {standard_task_runner.py:107} ERROR - Failed to execute job 463 for task Test_conexion (connection to server at "host.docker.internal" (192.168.65.254), port 5432 failed: FATAL:  password authentication failed for user "postgres"
; 660)
[2024-02-28T18:57:11.931+0000] {local_task_job_runner.py:234} INFO - Task exited with return code 1
[2024-02-28T18:57:11.944+0000] {taskinstance.py:3280} INFO - 0 downstream tasks scheduled from follow-on schedule check
